<?xml version="1.0" ?>
<robot name="turtlebot5" xmlns:xacro="http://ros.org/wiki/xacro">
  <xacro:include filename="$(find turtlebot3_description)/urdf/common_properties.xacro"/>
  <xacro:include filename="$(find turtlebot3_d435i_description)/urdf/mounted_turtlebot7new.gazebo.xacro"/>

  <link name="base_footprint"/>

  <joint name="base_joint" type="fixed">
    <parent link="base_footprint"/>
    <child link="base_link" />
    <origin xyz="0 0 0.010" rpy="0 0 0"/>
  </joint>

  <link name="base_link">
    <visual>
      <origin xyz="-0.064 0 0.0" rpy="0 0 0"/>
      <geometry>
        <mesh filename="package://turtlebot3_description/meshes/bases/waffle_pi_base_for_open_manipulator.stl" scale="0.001 0.001 0.001"/>
      </geometry>
      <material name="light_black"/>
    </visual>

    <collision>
      <origin xyz="-0.064 0 0.047" rpy="0 0 0"/>
      <geometry>
        <box size="0.266 0.266 0.094"/>
      </geometry>
    </collision>

    <inertial>
      <origin xyz="0.0 0 0.0" rpy="0 0 0"/>
      <mass value="1.6329594e+00"/>
      <inertia ixx="1.0" ixy="0.0" ixz="0.0"
               iyy="1.0" iyz="0.0"
               izz="1.0" />
      <!-- <inertia ixx="8.7002718e-03" ixy="-4.7576583e-05" ixz="1.1160499e-04"
               iyy="8.6195418e-03" iyz="-3.5422299e-06"
               izz="1.4612727e-02" />                -->
    </inertial>
  </link>

  <joint name="wheel_left_joint" type="continuous">
    <parent link="base_link"/>
    <child link="wheel_left_link"/>
    <origin xyz="0.0 0.144 0.023" rpy="-1.57 0 0"/>
    <axis xyz="0 0 1"/>
  </joint>

  <link name="wheel_left_link">
    <visual>
      <origin xyz="0 0 0" rpy="1.57 0 0"/>
      <geometry>
        <mesh filename="package://turtlebot3_description/meshes/wheels/left_tire.stl" scale="0.001 0.001 0.001"/>
      </geometry>
      <material name="dark"/>
    </visual>

    <collision>
      <origin xyz="0 0 0" rpy="0 0 0"/>
      <geometry>
        <cylinder length="0.018" radius="0.033"/>
      </geometry>
    </collision>

    <inertial>
      <origin xyz="0 0 0" />
      <mass value="2.8498940e-02" />
      <inertia ixx="1.1175580e-05" ixy="-4.2369783e-11" ixz="-5.9381719e-09"
               iyy="1.1192413e-05" iyz="-1.4400107e-11"
               izz="2.0712558e-05" />
      </inertial>
  </link>

  <joint name="wheel_right_joint" type="continuous">
    <parent link="base_link"/>
    <child link="wheel_right_link"/>
    <origin xyz="0.0 -0.144 0.023" rpy="-1.57 0 0"/>
    <axis xyz="0 0 1"/>
  </joint>

  <link name="wheel_right_link">
    <visual>
      <origin xyz="0 0 0" rpy="1.57 0 0"/>
      <geometry>
        <mesh filename="package://turtlebot3_description/meshes/wheels/right_tire.stl" scale="0.001 0.001 0.001"/>
      </geometry>
      <material name="dark"/>
    </visual>

    <collision>
      <origin xyz="0 0.001 0" rpy="0 0 0"/>
      <geometry>
        <cylinder length="0.018" radius="0.033"/>
      </geometry>
    </collision>

    <inertial>
      <origin xyz="0 0 0" />
      <mass value="2.8498940e-02" />
      <inertia ixx="1.1175580e-05" ixy="-4.2369783e-11" ixz="-5.9381719e-09"
               iyy="1.1192413e-05" iyz="-1.4400107e-11"
               izz="2.0712558e-05" />
      </inertial>
  </link>

  <joint name="caster_back_right_joint" type="fixed">
    <parent link="base_link"/>
    <child link="caster_back_right_link"/>
    <origin xyz="-0.177 -0.064 -0.004" rpy="-1.57 0 0"/>
  </joint>

  <link name="caster_back_right_link">
    <collision>
      <origin xyz="0 0.001 0" rpy="0 0 0"/>
      <geometry>
        <box size="0.030 0.009 0.020"/>
      </geometry>
    </collision>

    <inertial>
      <origin xyz="0 0 0" />
      <mass value="0.005" />
      <inertia ixx="0.001" ixy="0.0" ixz="0.0"
               iyy="0.001" iyz="0.0"
               izz="0.001" />
    </inertial>
  </link>

  <joint name="caster_back_left_joint" type="fixed">
    <parent link="base_link"/>
    <child link="caster_back_left_link"/>
    <origin xyz="-0.177 0.064 -0.004" rpy="-1.57 0 0"/>
  </joint>

  <link name="caster_back_left_link">
    <collision>
      <origin xyz="0 0.001 0" rpy="0 0 0"/>
      <geometry>
        <box size="0.030 0.009 0.020"/>
      </geometry>
    </collision>

    <inertial>
      <origin xyz="0 0 0" />
      <mass value="0.005" />
      <inertia ixx="0.001" ixy="0.0" ixz="0.0"
               iyy="0.001" iyz="0.0"
               izz="0.001" />
    </inertial>
  </link>

  <joint name="imu_joint" type="fixed">
    <parent link="base_link"/>
    <child link="imu_link"/>
    <origin xyz="0.0 0 0.068" rpy="0 0 0"/>
  </joint>

  <link name="imu_link"/>


  <joint name="scan_joint" type="fixed">
    <parent link="base_link"/>
    <child link="base_scan"/>
    <origin xyz="-0.024 0 0.122" rpy="0 0 0"/> 
  </joint>

  <link name="base_scan">
    <visual>
      <origin xyz="0 0 0.0" rpy="0 0 0"/>
      <geometry>
        <mesh filename="package://turtlebot3_description/meshes/sensors/lds.stl" scale="0.001 0.001 0.001"/>
      </geometry>
      <material name="dark"/>
    </visual>

    <collision>
      <origin xyz="0.015 0 -0.0065" rpy="0 0 0"/>
      <geometry>
        <cylinder length="0.0315" radius="0.045"/>
      </geometry>
    </collision>

    <inertial>
      <mass value="0.114" />
      <origin xyz="0 0 0" />
      <inertia ixx="0.001" ixy="0.0" ixz="0.0"
               iyy="0.001" iyz="0.0"
               izz="0.001" />
    </inertial>
  </link>

  <joint name="camera_joint" type="fixed">
    <origin xyz="0.073 -0.011 0.084" rpy="0 0 0"/>
    <parent link="base_link"/>
    <child link="camera_link"/>
  </joint>

  <link name="camera_link">
    <collision>
      <origin xyz="0.005 0.011 0.013" rpy="0 0 0"/>
      <geometry>
        <box size="0.015 0.030 0.027"/>
      </geometry>
    </collision>
  </link>

  <joint name="camera_rgb_joint" type="fixed">
    <origin xyz="0.003 0.011 0.009" rpy="0 0 0"/>
    <parent link="camera_link"/>
    <child link="camera_rgb_frame"/>
  </joint>
  <link name="camera_rgb_frame"/>

  <joint name="camera_rgb_optical_joint" type="fixed">
    <origin xyz="0 0 0" rpy="-1.57 0 -1.57"/>
    <parent link="camera_rgb_frame"/>
    <child link="camera_rgb_optical_frame"/>
  </joint>
  <link name="camera_rgb_optical_frame"/>

  <!-- Transmission macro -->
  <xacro:macro name="SimpleTransmission" params="joint n">
    <transmission name="tran${n}">
      <type>transmission_interface/SimpleTransmission</type>
      <joint name="${joint}">
        <hardwareInterface>hardware_interface/PositionJointInterface</hardwareInterface>
      </joint>
      <actuator name="motor${n}">
        <hardwareInterface>hardware_interface/PositionJointInterface</hardwareInterface>
        <mechanicalReduction>1</mechanicalReduction>
      </actuator>
    </transmission>
  </xacro:macro>

  <!-- Base fixed joint -->
  <joint name="base_fixed" type="fixed">
    <origin xyz="-0.092 0.0 0.091" rpy="0 0 0"/>
    <parent link="base_link"/>
    <child link="link1"/>
  </joint>

  <!-- Link 1 -->
  <link name="link1">
    <visual>
      <origin xyz="0 0 0" rpy="0 0 0"/>
      <geometry>
        <mesh filename="package://open_manipulator_description/meshes/chain_link1.stl" scale="0.001 0.001 0.001"/>
      </geometry>
      <material name="grey"/>
    </visual>

    <collision>
      <origin xyz="0 0 0" rpy="0 0 0"/>
      <geometry>
        <mesh filename="package://open_manipulator_description/meshes/chain_link1.stl" scale="0.001 0.001 0.001"/>
      </geometry>
    </collision>

  <!--    <inertial>
      <origin xyz="0 0 0" />
      <mass value="0.082" />
      <inertia ixx="0.1" ixy="0.0" ixz="0.0"
               iyy="0.1" iyz="0.0"
               izz="0.1" />
    </inertial>-->

     <inertial>
      <origin xyz="3.0876154e-04 0.0000000e+00 -1.2176461e-04" />
      <mass value="7.9119962e-02" />
      <inertia ixx="1.2505234e-05" ixy="0.0" ixz="-1.7855208e-07"
               iyy="2.1898364e-05" iyz="0.0"
               izz="1.9267361e-05" />
    </inertial>
  </link>

  <!-- Joint 1 -->
  <joint name="joint1" type="revolute">
    <parent link="link1"/>
    <child link="link2"/>
    <origin xyz="0.012 0.0 0.017" rpy="0 0 0"/>
    <axis xyz="0 0 1"/>
    <limit velocity="4.8" effort="1" lower="-2.827433388230814" upper="2.827433388230814" />
    <dynamics damping="0.1" friction="0.2"/>
  </joint>

  <!-- Transmission 1 -->
  <xacro:SimpleTransmission n="1" joint="joint1" />

  <!--  Link 2 -->
  <link name="link2">
    <visual>
      <origin xyz="0 0 0.018" rpy="0 0 0"/>
      <geometry>
        <mesh filename="package://open_manipulator_description/meshes/chain_link2.stl" scale="0.001 0.001 0.001"/>
      </geometry>
      <material name="grey"/>
    </visual>

    <collision>
      <origin xyz="0 0 0.018" rpy="0 0 0"/>
      <geometry>
        <mesh filename="package://open_manipulator_description/meshes/chain_link2.stl" scale="0.001 0.001 0.001"/>
      </geometry>
    </collision>

  <!--    <inertial>
      <origin xyz="0 0 0" />
      <mass value="0.098" />
      <inertia ixx="0.1" ixy="0.0" ixz="0.0"
               iyy="0.1" iyz="0.0"
               izz="0.1" />
    </inertial>-->

     <inertial>
      <origin xyz="-3.0184870e-04 5.4043684e-04 0.047433463999999995" />
      <mass value="9.8406837e-02" />
      <inertia ixx="3.4543422e-05" ixy="-1.6031095e-08" ixz="-3.8375155e-07"
               iyy="3.2689329e-05" iyz="2.8511935e-08"
               izz="1.8850320e-05" />
    </inertial>
  </link>

  <!--  Joint 2 -->
  <joint name="joint2" type="revolute">
    <parent link="link2"/>
    <child link="link3"/>
    <origin xyz="0.0 0.0 0.058" rpy="0 0 0"/>
    <axis xyz="0 1 0"/>
    <limit velocity="4.8" effort="1" lower="-1.790707812546182" upper="1.5707963267948966" />
    <dynamics damping="0.1" friction="0.2"/>
  </joint>

  <!-- Transmission 2 -->
  <xacro:SimpleTransmission n="2" joint="joint2" />

  <!--  Link 3 -->
  <link name="link3">
    <visual>
      <origin xyz="0 0 0" rpy="0 0 0"/>
      <geometry>
        <mesh filename="package://open_manipulator_description/meshes/chain_link3.stl" scale="0.001 0.001 0.001"/>
      </geometry>
      <material name="grey"/>
    </visual>

    <collision>
      <origin xyz="0 0 0" rpy="0 0 0"/>
      <geometry>
        <mesh filename="package://open_manipulator_description/meshes/chain_link3.stl" scale="0.001 0.001 0.001"/>
      </geometry>
    </collision>

  <!--    <inertial>
      <origin xyz="0 0 0" />
      <mass value="0.136" />
      <inertia ixx="0.1" ixy="0.0" ixz="0.0"
               iyy="0.1" iyz="0.0"
               izz="0.1" />
    </inertial>-->

     <inertial>
      <origin xyz="1.0308393e-02 3.7743363e-04 1.0170197e-01" />
      <mass value="1.3850917e-01" />
      <inertia ixx="3.3055381e-04" ixy="-9.7940978e-08" ixz="-3.8505711e-05"
               iyy="3.4290447e-04" iyz="-1.5717516e-06"
               izz="6.0346498e-05" />
    </inertial>
  </link>

  <!--  Joint 3 -->
  <joint name="joint3" type="revolute">
    <parent link="link3"/>
    <child link="link4"/>
    <origin xyz="0.024 0 0.128" rpy="0 0 0"/>
    <axis xyz="0 1 0"/>
    <limit velocity="4.8" effort="1" lower="-0.9424777960769379" upper="1.382300767579509" />
    <dynamics damping="0.1" friction="0.2"/>
  </joint>

  <!-- Transmission 3 -->
  <xacro:SimpleTransmission n="3" joint="joint3" />

  <!--  Link 4 -->
  <link name="link4">
    <visual>
      <origin xyz="0 0 0" rpy="0 0 0"/>
      <geometry>
        <mesh filename="package://open_manipulator_description/meshes/chain_link4.stl" scale="0.001 0.001 0.001"/>
      </geometry>
      <material name="grey"/>
    </visual>

    <collision>
      <origin xyz="0 0 0" rpy="0 0 0"/>
      <geometry>
        <mesh filename="package://open_manipulator_description/meshes/chain_link4.stl" scale="0.001 0.001 0.001"/>
      </geometry>
    </collision>

  <!--    <inertial>
      <origin xyz="0 0 0" />
      <mass value="0.131" />
      <inertia ixx="0.1" ixy="0.0" ixz="0.0"
               iyy="0.1" iyz="0.0"
               izz="0.1" />
    </inertial>-->

     <inertial>
      <origin xyz="9.0909590e-02 3.8929816e-04 2.2413279e-04" />
      <mass value="1.3274562e-01" />
      <inertia ixx="3.0654178e-05" ixy="-1.2764155e-06" ixz="-2.6874417e-07"
               iyy="2.4230292e-04" iyz="1.1559550e-08"
               izz="2.5155057e-04" />
    </inertial>
  </link>

  <!--  Joint 4 -->
  <joint name="joint4" type="revolute">
    <parent link="link4"/>
    <child link="link5"/>
    <origin xyz="0.124 0.0 0.0" rpy="0 0 0"/>
    <axis xyz="0 1 0"/>
    <limit velocity="4.8" effort="1" lower="-1.790707812546182" upper="2.0420352248333655" />
    <dynamics damping="0.1" friction="0.2"/>
  </joint>

  <!-- Transmission 4 -->
  <xacro:SimpleTransmission n="4" joint="joint4" />

  <!--  Link 5 -->
  <link name="link5">
    <visual>
      <origin xyz="0 0 0" rpy="0 0 0"/>
      <geometry>
        <mesh filename="package://open_manipulator_description/meshes/chain_link5.stl" scale="0.001 0.001 0.001"/>
      </geometry>
      <material name="grey"/>
    </visual>

    <collision>
      <origin xyz="0 0 0" rpy="0 0 0"/>
      <geometry>
        <mesh filename="package://open_manipulator_description/meshes/chain_link5.stl" scale="0.001 0.001 0.001"/>
      </geometry>
    </collision>

  <!--    <inertial>
      <origin xyz="0 0 0" />
      <mass value="0.141" />
      <inertia ixx="0.1" ixy="0.0" ixz="0.0"
               iyy="0.1" iyz="0.0"
               izz="0.1" />
    </inertial>-->

     <inertial>
      <origin xyz="4.4206755e-02 3.6839985e-07 8.9142216e-03" />
      <mass value="1.4327573e-01" />
      <inertia ixx="8.0870749e-05" ixy="0.0" ixz="-1.0157896e-06"
               iyy="7.5980465e-05" iyz="0.0"
               izz="9.3127351e-05" />
    </inertial>
  </link>

  <!--  Gripper link -->
  <link name="gripper_link">
    <visual>
      <origin xyz="0.0 0.0 0" rpy="0 0 0"/>
      <geometry>
        <mesh filename="package://open_manipulator_description/meshes/chain_link_grip_l.stl" scale="0.001 0.001 0.001"/>
      </geometry>
      <material name="grey"/>
    </visual>

    <collision>
      <origin xyz="0.0 0.0 0" rpy="0 0 0"/>
      <geometry>
        <mesh filename="package://open_manipulator_description/meshes/chain_link_grip_l.stl" scale="0.001 0.001 0.001"/>
      </geometry>
    </collision>

    <inertial>
      <origin xyz="0 0 0" />
      <mass value="0.017" />
      <inertia ixx="0.001" ixy="0.0" ixz="0.0"
               iyy="0.001" iyz="0.0"
               izz="0.001" />
    </inertial>

  <!--     <inertial>
      <origin xyz="${0.028 + 8.3720668e-03} ${0.0246 + 9.9696160e-03} -4.2836895e-07" />
      <mass value="3.2218127e-02" />
      <inertia ixx="9.5568826e-06" ixy="2.8424644e-06" ixz="-3.2829197e-10"
               iyy="2.2552871e-05" iyz="-3.1463634e-10"
               izz="1.7605306e-05" />
    </inertial>-->
  </link>

  <!--  Gripper joint -->
  <joint name="gripper" type="prismatic">
    <parent link="link5"/>
    <child link="gripper_link"/>
    <origin xyz="0.0817 0.019 0.0" rpy="0 0 0"/>
    <axis xyz="0 1 0"/>
    <limit velocity="4.8" effort="1" lower="-0.010" upper="0.019" />
    <dynamics damping="0.1" friction="0.2"/>
  </joint>

  <!-- Transmission 5 -->
  <xacro:SimpleTransmission n="5" joint="gripper" />

  <!--  Gripper link sub -->
  <link name="gripper_link_sub">
    <visual>
      <origin xyz="0.0 -0.0 0" rpy="0 0 0"/>
      <geometry>
        <mesh filename="package://open_manipulator_description/meshes/chain_link_grip_r.stl" scale="0.001 0.001 0.001"/>
      </geometry>
      <material name="grey"/>
    </visual>

    <collision>
      <origin xyz="0.0 -0.0 0" rpy="0 0 0"/>
      <geometry>
        <mesh filename="package://open_manipulator_description/meshes/chain_link_grip_r.stl" scale="0.001 0.001 0.001"/>
      </geometry>
    </collision>

    <inertial>
      <origin xyz="0 0 0" />
      <mass value="0.017" />
      <inertia ixx="0.001" ixy="0.0" ixz="0.0"
               iyy="0.001" iyz="0.0"
               izz="0.001" />
    </inertial>

  <!--     <inertial>
      <origin xyz="${0.028 + 8.3720668e-03} ${-0.0246 - 9.9696160e-03} -4.2836895e-07" />
      <mass value="3.2218127e-02" />
      <inertia ixx="9.5568826e-06" ixy="2.8424644e-06" ixz="-3.2829197e-10"
               iyy="2.2552871e-05" iyz="-3.1463634e-10"
               izz="1.7605306e-05" />
    </inertial>-->
  </link>

  <!--  Gripper joint sub -->
  <joint name="gripper_sub" type="prismatic">
    <parent link="link5"/>
    <child link="gripper_link_sub"/>
    <origin xyz="0.0817 -0.019 0" rpy="0 0 0"/>
    <axis xyz="0 -1 0"/>
    <limit velocity="4.8" effort="1" lower="-0.010" upper="0.019" />
    <mimic joint="gripper" multiplier="1"/>
    <dynamics damping="0.1" friction="0.2"/>
  </joint>

  <!-- Transmission 6 -->
  <xacro:SimpleTransmission n="6" joint="gripper_sub" />

  <!-- end effector joint -->
  <joint name="end_effector_joint" type="fixed">
    <origin xyz="0.130 0.0 0.0" rpy="0 0 0"/>
    <parent link="link5"/>
    <child link="end_effector_link"/>
    <dynamics damping="0.1" friction="0.2"/>
    <limit velocity="4.8" effort="1" lower="-0.010" upper="0.019" />
  </joint>

  <!-- end effector link -->
  <link name="end_effector_link">
    <visual>
      <origin xyz="0 0 0" rpy="0 0 0"/>
      <geometry>
        <box size="0.01 0.01 0.01" />
      </geometry>
      <material name="red"/>
     </visual>

    <inertial>
      <origin xyz="0.0 0.0 0.0" rpy="0 0 0"/>
      <mass value="0.001"/>
      <inertia ixx="0.001" ixy="0.0" ixz="0.0" iyy="0.001" iyz="0.0" izz="0.001" />
    </inertial>
  </link>

  <!-- Stand for realsense camera -->
  <link name="realsense2_camera_base_link">
    <visual>
      <origin xyz="0.0 0.0 0.0" rpy="1.570796327 0 0"/>
      <geometry>
        <mesh filename="package://turtlebot3_d435i_description/meshes/visual/stand_rs-d435_s01.stl" scale="0.001 0.001 0.001"/>
      </geometry>
      <material name="aluminum"/>
    </visual>
    <collision>
      <origin xyz="0 0 0" rpy="1.570796327 0 0"/>
      <geometry>
        <mesh filename="package://turtlebot3_d435i_description/meshes/collision/stand_rs-d435_s01.stl" scale="0.001 0.001 0.001"/>
      </geometry>
    </collision>
    <inertial>
      <mass value="0.05"/>
      <origin xyz="0 0 0" rpy="0 0 0"/>
      <inertia ixx="0.0015598989760400002" ixy="0.0" ixz="0.0" iyy="0.0015598989760400002" iyz="0.0" izz="0.00141942"/>
    </inertial>
  </link>

  <!-- Joint for stand on open manipulator X -->
  <joint name="realsense2_camera_stand_joint" type="fixed">
    <origin xyz="0.049 0 0.04" rpy="0 0 0"/>
    <parent link="link5"/>
    <child link="realsense2_camera_base_link"/>
  </joint>
  <material name="aluminum">
    <color rgba="0.5 0.5 0.5 1"/>
  </material>
  <material name="plastic">
    <color rgba="0.1 0.1 0.1 1"/>
  </material>

  <!-- camera body, with origin at bottom screw mount -->
  <joint name="realsense2_camera_joint" type="fixed">
    <origin xyz="0.01 0 0" rpy="0 0 0"/>
    <parent link="realsense2_camera_base_link"/>
    <child link="realsense2_camera_bottom_screw_frame"/>
  </joint>

  <link name="realsense2_camera_bottom_screw_frame"/>

  <joint name="realsense2_camera_link_joint" type="fixed">
    <origin xyz="0.010600000000000002 0.0175 0.0125" rpy="0 0 0"/>
    <parent link="realsense2_camera_bottom_screw_frame"/>
    <child link="realsense2_camera_link"/>
  </joint>

  <link name="realsense2_camera_link">
    <visual>
      <!-- the mesh origin is at front plate in between the two infrared camera axes -->
      <origin xyz="0.0043 -0.0175 0" rpy="1.5707963267948966 0 1.5707963267948966"/>
      <geometry>
        <mesh filename="package://realsense2_description/meshes/d435.dae"/>
      </geometry>
      <material name="aluminum"/>
    </visual>
    <collision>
      <origin xyz="0 -0.0175 0" rpy="0 0 0"/>
      <geometry>
        <box size="0.02505 0.09 0.025"/>
      </geometry>
    </collision>
    <inertial>
      <!-- The following are not reliable values, and should not be used for modeling -->
      <mass value="0.072"/>
      <origin xyz="0 0 0"/>
      <inertia ixx="0.003881243" ixy="0.0" ixz="0.0" iyy="0.000498940" iyz="0.0" izz="0.003879257"/>
    </inertial>
  </link>

  <!--added from dae file-->
  <!-- camera depth joints and links -->
  <joint name="realsense2_camera_depth_joint" type="fixed">
    <origin xyz="0 0 0" rpy="0 0 0"/>
    <parent link="realsense2_camera_link"/>
    <child link="realsense2_camera_depth_frame" />
  </joint>

  <link name="realsense2_camera_depth_frame"/>

  <joint name="realsense2_camera_depth_optical_joint" type="fixed">
    <origin xyz="0 0 0" rpy="-1.570796327 0 -1.570796327" />
    <parent link="realsense2_camera_depth_frame" />
    <child link="realsense2_camera_depth_optical_frame" />
  </joint>

  <link name="realsense2_camera_depth_optical_frame"/>

  <!-- camera left IR joints and links -->
  <joint name="realsense2_camera_left_ir_joint" type="fixed">
    <origin xyz="0 0 0" rpy="0 0 0" />
    <parent link="realsense2_camera_depth_frame" />
    <child link="realsense2_camera_left_ir_frame" />
  </joint>

  <link name="realsense2_camera_left_ir_frame"/>

  <joint name="realsense2_camera_left_ir_optical_joint" type="fixed">
    <origin xyz="0 0 0" rpy="-1.570796327 0 -1.570796327" />
    <parent link="realsense2_camera_left_ir_frame" />
    <child link="realsense2_camera_left_ir_optical_frame" />
  </joint>

  <link name="realsense2_camera_left_ir_optical_frame"/>

  <!-- camera right IR joints and links -->
  <joint name="realsense2_camera_right_ir_joint" type="fixed">
    <origin xyz="0 -0.050 0" rpy="0 0 0" />
    <parent link="realsense2_camera_depth_frame" />
    <child link="realsense2_camera_right_ir_frame" />
  </joint>

  <link name="realsense2_camera_right_ir_frame"/>

  <joint name="realsense2_camera_right_ir_optical_joint" type="fixed">
    <origin xyz="0 0 0" rpy="-1.570796327 0 -1.570796327" />
    <parent link="realsense2_camera_right_ir_frame" />
    <child link="realsense2_camera_right_ir_optical_frame" />
  </joint>

  <link name="realsense2_camera_right_ir_optical_frame"/>

  <!-- camera color joints and links -->
  <joint name="realsense2_camera_color_joint" type="fixed">
    <origin xyz="0 0.015 0" rpy="0 0 0" />
    <parent link="realsense2_camera_depth_frame" />
    <child link="realsense2_camera_color_frame" />
  </joint>
  <link name="realsense2_camera_color_frame"/>

  <joint name="realsense2_camera_color_optical_joint" type="fixed">
    <origin xyz="0 0 0" rpy="-1.570796327 0 -1.570796327" />
    <parent link="realsense2_camera_color_frame" />
    <child link="realsense2_camera_color_optical_frame" />
  </joint>

  <link name="realsense2_camera_color_optical_frame"/>

</robot>
